Workbook
Name Duenn_Kapazitaet: 'Settings'!$B$23
Name Duenn_nVelocity: 'Settings'!$B$22
Name Fenster: 'Settings'!$B$13
Name Referenz: 'Settings'!$B$12
Name Roadmap_Anteil: 'Settings'!$B$14
Name Rundung: 'Settings'!$B$15

Sheet Settings
A1: Settings of Golden products-edge
A2: Label | B2: Value | C2: Key (team.yaml)
A3: name | B3: Golden products-edge | C3: name
A4: unit | B4: PT | C4: unit
A5: features.products | B5: TRUE | C5: features.products
A6: features.po | B6: TRUE | C6: features.po
A7: features.production | B7: TRUE | C7: features.production
A8: sprint.length_days | B8: 14 | C8: sprint.length_days
A9: sprint.numbering | B9: yearly | C9: sprint.numbering
A10: sprint.first.id | B10: 2026.1 | C10: sprint.first.id
A11: sprint.first.start | B11: 46029 | C11: sprint.first.start
A12: Reference capacity (PT) | B12: 40 | C12: forecast.reference_capacity
A13: Window (sprints) | B13: 5 | C13: forecast.window
A14: Plannable share | B14: 0.75 | C14: forecast.roadmap_share
A15: Rounding (decimal places, rounded down) | B15: 1 | C15: forecast.rounding
A16: Trend mode (fixed at export) | B16: flat | C16: forecast.trend_mode
A17: forecast.horizon | B17: 3 | C17: forecast.horizon
A18: forecast.product_basis | B18: roadmap | C18: forecast.product_basis
A19: capacity.overhead_share | B19: 0 | C19: capacity.overhead_share
A20: capacity.rounding | B20: 1 | C20: capacity.rounding
A22: Thin history n. velocity (fewer values than the window, at least 3) | B22: =AND(COUNT('Forecast'!$K$4:$K$19)>=3,COUNT('Forecast'!$K$4:$K$19)<Fenster) -> FALSE
A23: Thin history capacity | B23: =AND(COUNT('Forecast'!$J$4:$J$19)>=3,COUNT('Forecast'!$J$4:$J$19)<Fenster) -> FALSE
A25: Current status | B25: 24.06.2026
A27: Yellow cells are inputs (settings and sprint values); all other cells are formulas. The trend mode is fixed in the formulas.

Sheet Forecast
A1: Forecast Golden products-edge
A2: Inputs are yellow; the columns to the right calculate like the web interface (calculation).
A3: Sprint | B3: Start | C3: End | D3: Commitment (PT) | E3: Velocity (PT) | F3: Scope creep | G3: Capacity (PD), recorded (input) | H3: Capacity (PD), calculated from people and calendar | I3: Source of the capacity | J3: Capacity (PD), recorded or calculated | K3: norm. velocity | L3: Count n. velocity | M3: Ø norm. velocity | N3: norm. velocity trend | O3: n. velocity known (avg or trend) | P3: Count capacity | Q3: Avg capacity | R3: Capacity trend | S3: Capacity known (avg or trend) | T3: Capacity for the Forecast PLAN (PD) | U3: Forecast PLAN (PT) | V3: Plannable (PT) | W3: Small stuff (PT) | X3: Fulfillment | Y3: Focus factor | Z3: Share of production access in the capacity | AA3: Capacity with production access (PD) | AB3: Capacity without production access (PD) | AC3: Forecast PLAN: up to with production access (PT) | AD3: Forecast PLAN: for all others (PT) | AE3: Σ planning per product (PT) | AF3: Forecast PLAN − Σ planning (PT)
A4: 2026.1 | B4: 46029 | C4: 46043 | D4: 32 | E4: 30 | G4: 40 | I4: recorded | J4: =IF(ISNUMBER(G4),G4,IF(ISNUMBER(H4),H4,"")) -> 40 | K4: =IF(AND(ISNUMBER(E4),ISNUMBER(J4),J4>0),E4/J4*Referenz,"") -> 30 | L4: =COUNT(K$4:K4) -> 1 | M4: =IF(NOT(ISNUMBER(K4)),"",IF(L4>=Fenster,AVERAGEIFS(K$4:K4,L$4:L4,">"&(L4-Fenster)),IF(AND(Duenn_nVelocity,L4>=3),AVERAGE(K$4:K4),""))) | N4: =IF(ISNUMBER(M4),"",IF(Duenn_nVelocity,"","")) | O4: =IF(ISNUMBER(M4),M4,IF(ISNUMBER(N4),N4,"")) | P4: =COUNT(J$4:J4) -> 1 | Q4: =IF(NOT(ISNUMBER(J4)),"",IF(P4>=Fenster,AVERAGEIFS(J$4:J4,P$4:P4,">"&(P4-Fenster)),IF(AND(Duenn_Kapazitaet,P4>=3),AVERAGE(J$4:J4),""))) | R4: =IF(ISNUMBER(Q4),"",IF(Duenn_Kapazitaet,"","")) | S4: =IF(ISNUMBER(Q4),Q4,IF(ISNUMBER(R4),R4,"")) | T4: =IF(ISNUMBER(J4),J4,R4) -> 40 | U4: =IF(AND(ISNUMBER(N4),ISNUMBER(T4)),MAX(0,ROUNDDOWN(N4/Referenz*T4,Rundung)),IF(ISNUMBER(D4),ROUNDDOWN(D4,Rundung),"")) -> 32 | V4: =IF(ISNUMBER(U4),U4*Roadmap_Anteil,"") -> 24 | W4: =IF(ISNUMBER(U4),U4-V4,"") -> 8 | X4: =IF(AND(ISNUMBER(E4),ISNUMBER(D4),D4<>0),E4/D4,"") -> 0.9375 | Y4: =IF(AND(ISNUMBER(E4),ISNUMBER(J4),J4>0),E4/J4,"") -> 0.75 | Z4: 0.11764706 | AA4: =IF(ISNUMBER(T4),T4*Z4,"") -> 4.7058824 | AB4: =IF(ISNUMBER(T4),T4*(1-Z4),"") -> 35.294118 | AC4: =IF(ISNUMBER(U4),U4*Z4,"") -> 3.7647059 | AD4: =IF(ISNUMBER(U4),U4*(1-Z4),"") -> 28.235294 | AE4: =IF(COUNTIFS('Product values'!$A$2:$A$69,A4,'Product values'!$G$2:$G$69,"<>")=0,"",SUMIFS('Product values'!$G$2:$G$69,'Product values'!$A$2:$A$69,A4)) -> 26.5 | AF4: =IF(AND(ISNUMBER(U4),ISNUMBER(AE4)),U4-AE4,"") -> 5.5
A5: 2026.2 | B5: 46043 | C5: 46057 | D5: 35 | E5: 34 | G5: 44 | I5: recorded | J5: =IF(ISNUMBER(G5),G5,IF(ISNUMBER(H5),H5,"")) -> 44 | K5: =IF(AND(ISNUMBER(E5),ISNUMBER(J5),J5>0),E5/J5*Referenz,"") -> 30.909091 | L5: =COUNT(K$4:K5) -> 2 | M5: =IF(NOT(ISNUMBER(K5)),"",IF(L5>=Fenster,AVERAGEIFS(K$4:K5,L$4:L5,">"&(L5-Fenster)),IF(AND(Duenn_nVelocity,L5>=3),AVERAGE(K$4:K5),""))) | N5: =IF(ISNUMBER(M5),"",IF(Duenn_nVelocity,IF(ISNUMBER(O4),O4,""),IF(ISNUMBER(O4),O4,""))) | O5: =IF(ISNUMBER(M5),M5,IF(ISNUMBER(N5),N5,"")) | P5: =COUNT(J$4:J5) -> 2 | Q5: =IF(NOT(ISNUMBER(J5)),"",IF(P5>=Fenster,AVERAGEIFS(J$4:J5,P$4:P5,">"&(P5-Fenster)),IF(AND(Duenn_Kapazitaet,P5>=3),AVERAGE(J$4:J5),""))) | R5: =IF(ISNUMBER(Q5),"",IF(Duenn_Kapazitaet,IF(ISNUMBER(S4),S4,""),IF(ISNUMBER(S4),S4,""))) | S5: =IF(ISNUMBER(Q5),Q5,IF(ISNUMBER(R5),R5,"")) | T5: =IF(ISNUMBER(J5),J5,R5) -> 44 | U5: =IF(AND(ISNUMBER(N5),ISNUMBER(T5)),MAX(0,ROUNDDOWN(N5/Referenz*T5,Rundung)),IF(ISNUMBER(D5),ROUNDDOWN(D5,Rundung),"")) -> 35 | V5: =IF(ISNUMBER(U5),U5*Roadmap_Anteil,"") -> 26.25 | W5: =IF(ISNUMBER(U5),U5-V5,"") -> 8.75 | X5: =IF(AND(ISNUMBER(E5),ISNUMBER(D5),D5<>0),E5/D5,"") -> 0.97142857 | Y5: =IF(AND(ISNUMBER(E5),ISNUMBER(J5),J5>0),E5/J5,"") -> 0.77272727 | Z5: 0.11627907 | AA5: =IF(ISNUMBER(T5),T5*Z5,"") -> 5.1162791 | AB5: =IF(ISNUMBER(T5),T5*(1-Z5),"") -> 38.883721 | AC5: =IF(ISNUMBER(U5),U5*Z5,"") -> 4.0697674 | AD5: =IF(ISNUMBER(U5),U5*(1-Z5),"") -> 30.930233 | AE5: =IF(COUNTIFS('Product values'!$A$2:$A$69,A5,'Product values'!$G$2:$G$69,"<>")=0,"",SUMIFS('Product values'!$G$2:$G$69,'Product values'!$A$2:$A$69,A5)) -> 27 | AF5: =IF(AND(ISNUMBER(U5),ISNUMBER(AE5)),U5-AE5,"") -> 8
A6: 2026.3 | B6: 46057 | C6: 46071 | D6: 33 | E6: 28 | G6: 38 | I6: recorded | J6: =IF(ISNUMBER(G6),G6,IF(ISNUMBER(H6),H6,"")) -> 38 | K6: =IF(AND(ISNUMBER(E6),ISNUMBER(J6),J6>0),E6/J6*Referenz,"") -> 29.473684 | L6: =COUNT(K$4:K6) -> 3 | M6: =IF(NOT(ISNUMBER(K6)),"",IF(L6>=Fenster,AVERAGEIFS(K$4:K6,L$4:L6,">"&(L6-Fenster)),IF(AND(Duenn_nVelocity,L6>=3),AVERAGE(K$4:K6),""))) | N6: =IF(ISNUMBER(M6),"",IF(Duenn_nVelocity,IF(ISNUMBER(O5),O5,""),IF(ISNUMBER(O5),O5,""))) | O6: =IF(ISNUMBER(M6),M6,IF(ISNUMBER(N6),N6,"")) | P6: =COUNT(J$4:J6) -> 3 | Q6: =IF(NOT(ISNUMBER(J6)),"",IF(P6>=Fenster,AVERAGEIFS(J$4:J6,P$4:P6,">"&(P6-Fenster)),IF(AND(Duenn_Kapazitaet,P6>=3),AVERAGE(J$4:J6),""))) | R6: =IF(ISNUMBER(Q6),"",IF(Duenn_Kapazitaet,IF(ISNUMBER(S5),S5,""),IF(ISNUMBER(S5),S5,""))) | S6: =IF(ISNUMBER(Q6),Q6,IF(ISNUMBER(R6),R6,"")) | T6: =IF(ISNUMBER(J6),J6,R6) -> 38 | U6: =IF(AND(ISNUMBER(N6),ISNUMBER(T6)),MAX(0,ROUNDDOWN(N6/Referenz*T6,Rundung)),IF(ISNUMBER(D6),ROUNDDOWN(D6,Rundung),"")) -> 33 | V6: =IF(ISNUMBER(U6),U6*Roadmap_Anteil,"") -> 24.75 | W6: =IF(ISNUMBER(U6),U6-V6,"") -> 8.25 | X6: =IF(AND(ISNUMBER(E6),ISNUMBER(D6),D6<>0),E6/D6,"") -> 0.84848485 | Y6: =IF(AND(ISNUMBER(E6),ISNUMBER(J6),J6>0),E6/J6,"") -> 0.73684211 | Z6: 0.11990408 | AA6: =IF(ISNUMBER(T6),T6*Z6,"") -> 4.5563549 | AB6: =IF(ISNUMBER(T6),T6*(1-Z6),"") -> 33.443645 | AC6: =IF(ISNUMBER(U6),U6*Z6,"") -> 3.9568345 | AD6: =IF(ISNUMBER(U6),U6*(1-Z6),"") -> 29.043165 | AE6: =IF(COUNTIFS('Product values'!$A$2:$A$69,A6,'Product values'!$G$2:$G$69,"<>")=0,"",SUMIFS('Product values'!$G$2:$G$69,'Product values'!$A$2:$A$69,A6)) -> 18 | AF6: =IF(AND(ISNUMBER(U6),ISNUMBER(AE6)),U6-AE6,"") -> 15
A7: 2026.4 | B7: 46071 | C7: 46085 | D7: 36 | E7: 36 | G7: 42 | I7: recorded | J7: =IF(ISNUMBER(G7),G7,IF(ISNUMBER(H7),H7,"")) -> 42 | K7: =IF(AND(ISNUMBER(E7),ISNUMBER(J7),J7>0),E7/J7*Referenz,"") -> 34.285714 | L7: =COUNT(K$4:K7) -> 4 | M7: =IF(NOT(ISNUMBER(K7)),"",IF(L7>=Fenster,AVERAGEIFS(K$4:K7,L$4:L7,">"&(L7-Fenster)),IF(AND(Duenn_nVelocity,L7>=3),AVERAGE(K$4:K7),""))) | N7: =IF(ISNUMBER(M7),"",IF(Duenn_nVelocity,IF(ISNUMBER(O6),O6,""),IF(ISNUMBER(O6),O6,""))) | O7: =IF(ISNUMBER(M7),M7,IF(ISNUMBER(N7),N7,"")) | P7: =COUNT(J$4:J7) -> 4 | Q7: =IF(NOT(ISNUMBER(J7)),"",IF(P7>=Fenster,AVERAGEIFS(J$4:J7,P$4:P7,">"&(P7-Fenster)),IF(AND(Duenn_Kapazitaet,P7>=3),AVERAGE(J$4:J7),""))) | R7: =IF(ISNUMBER(Q7),"",IF(Duenn_Kapazitaet,IF(ISNUMBER(S6),S6,""),IF(ISNUMBER(S6),S6,""))) | S7: =IF(ISNUMBER(Q7),Q7,IF(ISNUMBER(R7),R7,"")) | T7: =IF(ISNUMBER(J7),J7,R7) -> 42 | U7: =IF(AND(ISNUMBER(N7),ISNUMBER(T7)),MAX(0,ROUNDDOWN(N7/Referenz*T7,Rundung)),IF(ISNUMBER(D7),ROUNDDOWN(D7,Rundung),"")) -> 36 | V7: =IF(ISNUMBER(U7),U7*Roadmap_Anteil,"") -> 27 | W7: =IF(ISNUMBER(U7),U7-V7,"") -> 9 | X7: =IF(AND(ISNUMBER(E7),ISNUMBER(D7),D7<>0),E7/D7,"") -> 1 | Y7: =IF(AND(ISNUMBER(E7),ISNUMBER(J7),J7>0),E7/J7,"") -> 0.85714286 | Z7: 0.12224939 | AA7: =IF(ISNUMBER(T7),T7*Z7,"") -> 5.1344743 | AB7: =IF(ISNUMBER(T7),T7*(1-Z7),"") -> 36.865526 | AC7: =IF(ISNUMBER(U7),U7*Z7,"") -> 4.400978 | AD7: =IF(ISNUMBER(U7),U7*(1-Z7),"") -> 31.599022 | AE7: =IF(COUNTIFS('Product values'!$A$2:$A$69,A7,'Product values'!$G$2:$G$69,"<>")=0,"",SUMIFS('Product values'!$G$2:$G$69,'Product values'!$A$2:$A$69,A7)) | AF7: =IF(AND(ISNUMBER(U7),ISNUMBER(AE7)),U7-AE7,"")
A8: 2026.5 | B8: 46085 | C8: 46099 | D8: 34 | E8: 33 | G8: 40 | I8: recorded | J8: =IF(ISNUMBER(G8),G8,IF(ISNUMBER(H8),H8,"")) -> 40 | K8: =IF(AND(ISNUMBER(E8),ISNUMBER(J8),J8>0),E8/J8*Referenz,"") -> 33 | L8: =COUNT(K$4:K8) -> 5 | M8: =IF(NOT(ISNUMBER(K8)),"",IF(L8>=Fenster,AVERAGEIFS(K$4:K8,L$4:L8,">"&(L8-Fenster)),IF(AND(Duenn_nVelocity,L8>=3),AVERAGE(K$4:K8),""))) -> 31.533698 | N8: =IF(ISNUMBER(M8),"",IF(Duenn_nVelocity,IF(ISNUMBER(O7),O7,""),IF(ISNUMBER(O7),O7,""))) | O8: =IF(ISNUMBER(M8),M8,IF(ISNUMBER(N8),N8,"")) -> 31.533698 | P8: =COUNT(J$4:J8) -> 5 | Q8: =IF(NOT(ISNUMBER(J8)),"",IF(P8>=Fenster,AVERAGEIFS(J$4:J8,P$4:P8,">"&(P8-Fenster)),IF(AND(Duenn_Kapazitaet,P8>=3),AVERAGE(J$4:J8),""))) -> 40.8 | R8: =IF(ISNUMBER(Q8),"",IF(Duenn_Kapazitaet,IF(ISNUMBER(S7),S7,""),IF(ISNUMBER(S7),S7,""))) | S8: =IF(ISNUMBER(Q8),Q8,IF(ISNUMBER(R8),R8,"")) -> 40.8 | T8: =IF(ISNUMBER(J8),J8,R8) -> 40 | U8: =IF(AND(ISNUMBER(N8),ISNUMBER(T8)),MAX(0,ROUNDDOWN(N8/Referenz*T8,Rundung)),IF(ISNUMBER(D8),ROUNDDOWN(D8,Rundung),"")) -> 34 | V8: =IF(ISNUMBER(U8),U8*Roadmap_Anteil,"") -> 25.5 | W8: =IF(ISNUMBER(U8),U8-V8,"") -> 8.5 | X8: =IF(AND(ISNUMBER(E8),ISNUMBER(D8),D8<>0),E8/D8,"") -> 0.97058824 | Y8: =IF(AND(ISNUMBER(E8),ISNUMBER(J8),J8>0),E8/J8,"") -> 0.825 | Z8: 0.11627907 | AA8: =IF(ISNUMBER(T8),T8*Z8,"") -> 4.6511628 | AB8: =IF(ISNUMBER(T8),T8*(1-Z8),"") -> 35.348837 | AC8: =IF(ISNUMBER(U8),U8*Z8,"") -> 3.9534884 | AD8: =IF(ISNUMBER(U8),U8*(1-Z8),"") -> 30.046512 | AE8: =IF(COUNTIFS('Product values'!$A$2:$A$69,A8,'Product values'!$G$2:$G$69,"<>")=0,"",SUMIFS('Product values'!$G$2:$G$69,'Product values'!$A$2:$A$69,A8)) | AF8: =IF(AND(ISNUMBER(U8),ISNUMBER(AE8)),U8-AE8,"")
A9: 2026.6 | B9: 46099 | C9: 46113 | D9: 32 | E9: 31 | G9: 41 | I9: recorded | J9: =IF(ISNUMBER(G9),G9,IF(ISNUMBER(H9),H9,"")) -> 41 | K9: =IF(AND(ISNUMBER(E9),ISNUMBER(J9),J9>0),E9/J9*Referenz,"") -> 30.243902 | L9: =COUNT(K$4:K9) -> 6 | M9: =IF(NOT(ISNUMBER(K9)),"",IF(L9>=Fenster,AVERAGEIFS(K$4:K9,L$4:L9,">"&(L9-Fenster)),IF(AND(Duenn_nVelocity,L9>=3),AVERAGE(K$4:K9),""))) -> 31.582478 | N9: =IF(ISNUMBER(M9),"",IF(Duenn_nVelocity,IF(ISNUMBER(O8),O8,""),IF(ISNUMBER(O8),O8,""))) | O9: =IF(ISNUMBER(M9),M9,IF(ISNUMBER(N9),N9,"")) -> 31.582478 | P9: =COUNT(J$4:J9) -> 6 | Q9: =IF(NOT(ISNUMBER(J9)),"",IF(P9>=Fenster,AVERAGEIFS(J$4:J9,P$4:P9,">"&(P9-Fenster)),IF(AND(Duenn_Kapazitaet,P9>=3),AVERAGE(J$4:J9),""))) -> 41 | R9: =IF(ISNUMBER(Q9),"",IF(Duenn_Kapazitaet,IF(ISNUMBER(S8),S8,""),IF(ISNUMBER(S8),S8,""))) | S9: =IF(ISNUMBER(Q9),Q9,IF(ISNUMBER(R9),R9,"")) -> 41 | T9: =IF(ISNUMBER(J9),J9,R9) -> 41 | U9: =IF(AND(ISNUMBER(N9),ISNUMBER(T9)),MAX(0,ROUNDDOWN(N9/Referenz*T9,Rundung)),IF(ISNUMBER(D9),ROUNDDOWN(D9,Rundung),"")) -> 32 | V9: =IF(ISNUMBER(U9),U9*Roadmap_Anteil,"") -> 24 | W9: =IF(ISNUMBER(U9),U9-V9,"") -> 8 | X9: =IF(AND(ISNUMBER(E9),ISNUMBER(D9),D9<>0),E9/D9,"") -> 0.96875 | Y9: =IF(AND(ISNUMBER(E9),ISNUMBER(J9),J9>0),E9/J9,"") -> 0.75609756 | Z9: 0.040540541 | AA9: =IF(ISNUMBER(T9),T9*Z9,"") -> 1.6621622 | AB9: =IF(ISNUMBER(T9),T9*(1-Z9),"") -> 39.337838 | AC9: =IF(ISNUMBER(U9),U9*Z9,"") -> 1.2972973 | AD9: =IF(ISNUMBER(U9),U9*(1-Z9),"") -> 30.702703 | AE9: =IF(COUNTIFS('Product values'!$A$2:$A$69,A9,'Product values'!$G$2:$G$69,"<>")=0,"",SUMIFS('Product values'!$G$2:$G$69,'Product values'!$A$2:$A$69,A9)) | AF9: =IF(AND(ISNUMBER(U9),ISNUMBER(AE9)),U9-AE9,"")
A10: 2026.7 | B10: 46113 | C10: 46127 | H10: 67.2 | I10: Calendar, absences unknown | J10: =IF(ISNUMBER(G10),G10,IF(ISNUMBER(H10),H10,"")) -> 67.2 | K10: =IF(AND(ISNUMBER(E10),ISNUMBER(J10),J10>0),E10/J10*Referenz,"") | L10: =COUNT(K$4:K10) -> 6 | M10: =IF(NOT(ISNUMBER(K10)),"",IF(L10>=Fenster,AVERAGEIFS(K$4:K10,L$4:L10,">"&(L10-Fenster)),IF(AND(Duenn_nVelocity,L10>=3),AVERAGE(K$4:K10),""))) | N10: =IF(ISNUMBER(M10),"",IF(Duenn_nVelocity,IF(ISNUMBER(O9),O9,""),IF(ISNUMBER(O9),O9,""))) -> 31.582478 | O10: =IF(ISNUMBER(M10),M10,IF(ISNUMBER(N10),N10,"")) -> 31.582478 | P10: =COUNT(J$4:J10) -> 7 | Q10: =IF(NOT(ISNUMBER(J10)),"",IF(P10>=Fenster,AVERAGEIFS(J$4:J10,P$4:P10,">"&(P10-Fenster)),IF(AND(Duenn_Kapazitaet,P10>=3),AVERAGE(J$4:J10),""))) -> 45.64 | R10: =IF(ISNUMBER(Q10),"",IF(Duenn_Kapazitaet,IF(ISNUMBER(S9),S9,""),IF(ISNUMBER(S9),S9,""))) | S10: =IF(ISNUMBER(Q10),Q10,IF(ISNUMBER(R10),R10,"")) -> 45.64 | T10: =IF(ISNUMBER(J10),J10,R10) -> 67.2 | U10: =IF(AND(ISNUMBER(N10),ISNUMBER(T10)),MAX(0,ROUNDDOWN(N10/Referenz*T10,Rundung)),IF(ISNUMBER(D10),ROUNDDOWN(D10,Rundung),"")) -> 53 | V10: =IF(ISNUMBER(U10),U10*Roadmap_Anteil,"") -> 39.75 | W10: =IF(ISNUMBER(U10),U10-V10,"") -> 13.25 | X10: =IF(AND(ISNUMBER(E10),ISNUMBER(D10),D10<>0),E10/D10,"") | Y10: =IF(AND(ISNUMBER(E10),ISNUMBER(J10),J10>0),E10/J10,"") | AE10: =IF(COUNTIFS('Product values'!$A$2:$A$69,A10,'Product values'!$G$2:$G$69,"<>")=0,"",SUMIFS('Product values'!$G$2:$G$69,'Product values'!$A$2:$A$69,A10)) | AF10: =IF(AND(ISNUMBER(U10),ISNUMBER(AE10)),U10-AE10,"")
A11: 2026.8 | B11: 46127 | C11: 46141 | H11: 76 | I11: Calendar, absences unknown | J11: =IF(ISNUMBER(G11),G11,IF(ISNUMBER(H11),H11,"")) -> 76 | K11: =IF(AND(ISNUMBER(E11),ISNUMBER(J11),J11>0),E11/J11*Referenz,"") | L11: =COUNT(K$4:K11) -> 6 | M11: =IF(NOT(ISNUMBER(K11)),"",IF(L11>=Fenster,AVERAGEIFS(K$4:K11,L$4:L11,">"&(L11-Fenster)),IF(AND(Duenn_nVelocity,L11>=3),AVERAGE(K$4:K11),""))) | N11: =IF(ISNUMBER(M11),"",IF(Duenn_nVelocity,IF(ISNUMBER(O10),O10,""),IF(ISNUMBER(O10),O10,""))) -> 31.582478 | O11: =IF(ISNUMBER(M11),M11,IF(ISNUMBER(N11),N11,"")) -> 31.582478 | P11: =COUNT(J$4:J11) -> 8 | Q11: =IF(NOT(ISNUMBER(J11)),"",IF(P11>=Fenster,AVERAGEIFS(J$4:J11,P$4:P11,">"&(P11-Fenster)),IF(AND(Duenn_Kapazitaet,P11>=3),AVERAGE(J$4:J11),""))) -> 53.24 | R11: =IF(ISNUMBER(Q11),"",IF(Duenn_Kapazitaet,IF(ISNUMBER(S10),S10,""),IF(ISNUMBER(S10),S10,""))) | S11: =IF(ISNUMBER(Q11),Q11,IF(ISNUMBER(R11),R11,"")) -> 53.24 | T11: =IF(ISNUMBER(J11),J11,R11) -> 76 | U11: =IF(AND(ISNUMBER(N11),ISNUMBER(T11)),MAX(0,ROUNDDOWN(N11/Referenz*T11,Rundung)),IF(ISNUMBER(D11),ROUNDDOWN(D11,Rundung),"")) -> 60 | V11: =IF(ISNUMBER(U11),U11*Roadmap_Anteil,"") -> 45 | W11: =IF(ISNUMBER(U11),U11-V11,"") -> 15 | X11: =IF(AND(ISNUMBER(E11),ISNUMBER(D11),D11<>0),E11/D11,"") | Y11: =IF(AND(ISNUMBER(E11),ISNUMBER(J11),J11>0),E11/J11,"") | AE11: =IF(COUNTIFS('Product values'!$A$2:$A$69,A11,'Product values'!$G$2:$G$69,"<>")=0,"",SUMIFS('Product values'!$G$2:$G$69,'Product values'!$A$2:$A$69,A11)) | AF11: =IF(AND(ISNUMBER(U11),ISNUMBER(AE11)),U11-AE11,"")
A12: 2026.9 | B12: 46141 | C12: 46155 | H12: 70.6 | I12: Calendar, absences unknown | J12: =IF(ISNUMBER(G12),G12,IF(ISNUMBER(H12),H12,"")) -> 70.6 | K12: =IF(AND(ISNUMBER(E12),ISNUMBER(J12),J12>0),E12/J12*Referenz,"") | L12: =COUNT(K$4:K12) -> 6 | M12: =IF(NOT(ISNUMBER(K12)),"",IF(L12>=Fenster,AVERAGEIFS(K$4:K12,L$4:L12,">"&(L12-Fenster)),IF(AND(Duenn_nVelocity,L12>=3),AVERAGE(K$4:K12),""))) | N12: =IF(ISNUMBER(M12),"",IF(Duenn_nVelocity,IF(ISNUMBER(O11),O11,""),IF(ISNUMBER(O11),O11,""))) -> 31.582478 | O12: =IF(ISNUMBER(M12),M12,IF(ISNUMBER(N12),N12,"")) -> 31.582478 | P12: =COUNT(J$4:J12) -> 9 | Q12: =IF(NOT(ISNUMBER(J12)),"",IF(P12>=Fenster,AVERAGEIFS(J$4:J12,P$4:P12,">"&(P12-Fenster)),IF(AND(Duenn_Kapazitaet,P12>=3),AVERAGE(J$4:J12),""))) -> 58.96 | R12: =IF(ISNUMBER(Q12),"",IF(Duenn_Kapazitaet,IF(ISNUMBER(S11),S11,""),IF(ISNUMBER(S11),S11,""))) | S12: =IF(ISNUMBER(Q12),Q12,IF(ISNUMBER(R12),R12,"")) -> 58.96 | T12: =IF(ISNUMBER(J12),J12,R12) -> 70.6 | U12: =IF(AND(ISNUMBER(N12),ISNUMBER(T12)),MAX(0,ROUNDDOWN(N12/Referenz*T12,Rundung)),IF(ISNUMBER(D12),ROUNDDOWN(D12,Rundung),"")) -> 55.7 | V12: =IF(ISNUMBER(U12),U12*Roadmap_Anteil,"") -> 41.775 | W12: =IF(ISNUMBER(U12),U12-V12,"") -> 13.925 | X12: =IF(AND(ISNUMBER(E12),ISNUMBER(D12),D12<>0),E12/D12,"") | Y12: =IF(AND(ISNUMBER(E12),ISNUMBER(J12),J12>0),E12/J12,"") | AE12: =IF(COUNTIFS('Product values'!$A$2:$A$69,A12,'Product values'!$G$2:$G$69,"<>")=0,"",SUMIFS('Product values'!$G$2:$G$69,'Product values'!$A$2:$A$69,A12)) | AF12: =IF(AND(ISNUMBER(U12),ISNUMBER(AE12)),U12-AE12,"")
A13: 2026.10 | B13: 46155 | C13: 46169 | H13: 64 | I13: Calendar, absences unknown | J13: =IF(ISNUMBER(G13),G13,IF(ISNUMBER(H13),H13,"")) -> 64 | K13: =IF(AND(ISNUMBER(E13),ISNUMBER(J13),J13>0),E13/J13*Referenz,"") | L13: =COUNT(K$4:K13) -> 6 | M13: =IF(NOT(ISNUMBER(K13)),"",IF(L13>=Fenster,AVERAGEIFS(K$4:K13,L$4:L13,">"&(L13-Fenster)),IF(AND(Duenn_nVelocity,L13>=3),AVERAGE(K$4:K13),""))) | N13: =IF(ISNUMBER(M13),"",IF(Duenn_nVelocity,IF(ISNUMBER(O12),O12,""),IF(ISNUMBER(O12),O12,""))) -> 31.582478 | O13: =IF(ISNUMBER(M13),M13,IF(ISNUMBER(N13),N13,"")) -> 31.582478 | P13: =COUNT(J$4:J13) -> 10 | Q13: =IF(NOT(ISNUMBER(J13)),"",IF(P13>=Fenster,AVERAGEIFS(J$4:J13,P$4:P13,">"&(P13-Fenster)),IF(AND(Duenn_Kapazitaet,P13>=3),AVERAGE(J$4:J13),""))) -> 63.76 | R13: =IF(ISNUMBER(Q13),"",IF(Duenn_Kapazitaet,IF(ISNUMBER(S12),S12,""),IF(ISNUMBER(S12),S12,""))) | S13: =IF(ISNUMBER(Q13),Q13,IF(ISNUMBER(R13),R13,"")) -> 63.76 | T13: =IF(ISNUMBER(J13),J13,R13) -> 64 | U13: =IF(AND(ISNUMBER(N13),ISNUMBER(T13)),MAX(0,ROUNDDOWN(N13/Referenz*T13,Rundung)),IF(ISNUMBER(D13),ROUNDDOWN(D13,Rundung),"")) -> 50.5 | V13: =IF(ISNUMBER(U13),U13*Roadmap_Anteil,"") -> 37.875 | W13: =IF(ISNUMBER(U13),U13-V13,"") -> 12.625 | X13: =IF(AND(ISNUMBER(E13),ISNUMBER(D13),D13<>0),E13/D13,"") | Y13: =IF(AND(ISNUMBER(E13),ISNUMBER(J13),J13>0),E13/J13,"") | AE13: =IF(COUNTIFS('Product values'!$A$2:$A$69,A13,'Product values'!$G$2:$G$69,"<>")=0,"",SUMIFS('Product values'!$G$2:$G$69,'Product values'!$A$2:$A$69,A13)) | AF13: =IF(AND(ISNUMBER(U13),ISNUMBER(AE13)),U13-AE13,"")
A14: 2026.11 | B14: 46169 | C14: 46183 | H14: 72 | I14: Calendar, absences unknown | J14: =IF(ISNUMBER(G14),G14,IF(ISNUMBER(H14),H14,"")) -> 72 | K14: =IF(AND(ISNUMBER(E14),ISNUMBER(J14),J14>0),E14/J14*Referenz,"") | L14: =COUNT(K$4:K14) -> 6 | M14: =IF(NOT(ISNUMBER(K14)),"",IF(L14>=Fenster,AVERAGEIFS(K$4:K14,L$4:L14,">"&(L14-Fenster)),IF(AND(Duenn_nVelocity,L14>=3),AVERAGE(K$4:K14),""))) | N14: =IF(ISNUMBER(M14),"",IF(Duenn_nVelocity,IF(ISNUMBER(O13),O13,""),IF(ISNUMBER(O13),O13,""))) -> 31.582478 | O14: =IF(ISNUMBER(M14),M14,IF(ISNUMBER(N14),N14,"")) -> 31.582478 | P14: =COUNT(J$4:J14) -> 11 | Q14: =IF(NOT(ISNUMBER(J14)),"",IF(P14>=Fenster,AVERAGEIFS(J$4:J14,P$4:P14,">"&(P14-Fenster)),IF(AND(Duenn_Kapazitaet,P14>=3),AVERAGE(J$4:J14),""))) -> 69.96 | R14: =IF(ISNUMBER(Q14),"",IF(Duenn_Kapazitaet,IF(ISNUMBER(S13),S13,""),IF(ISNUMBER(S13),S13,""))) | S14: =IF(ISNUMBER(Q14),Q14,IF(ISNUMBER(R14),R14,"")) -> 69.96 | T14: =IF(ISNUMBER(J14),J14,R14) -> 72 | U14: =IF(AND(ISNUMBER(N14),ISNUMBER(T14)),MAX(0,ROUNDDOWN(N14/Referenz*T14,Rundung)),IF(ISNUMBER(D14),ROUNDDOWN(D14,Rundung),"")) -> 56.8 | V14: =IF(ISNUMBER(U14),U14*Roadmap_Anteil,"") -> 42.6 | W14: =IF(ISNUMBER(U14),U14-V14,"") -> 14.2 | X14: =IF(AND(ISNUMBER(E14),ISNUMBER(D14),D14<>0),E14/D14,"") | Y14: =IF(AND(ISNUMBER(E14),ISNUMBER(J14),J14>0),E14/J14,"") | AE14: =IF(COUNTIFS('Product values'!$A$2:$A$69,A14,'Product values'!$G$2:$G$69,"<>")=0,"",SUMIFS('Product values'!$G$2:$G$69,'Product values'!$A$2:$A$69,A14)) | AF14: =IF(AND(ISNUMBER(U14),ISNUMBER(AE14)),U14-AE14,"")
A15: 2026.12 | B15: 46183 | C15: 46197 | H15: 74.2 | I15: Calendar, absences unknown | J15: =IF(ISNUMBER(G15),G15,IF(ISNUMBER(H15),H15,"")) -> 74.2 | K15: =IF(AND(ISNUMBER(E15),ISNUMBER(J15),J15>0),E15/J15*Referenz,"") | L15: =COUNT(K$4:K15) -> 6 | M15: =IF(NOT(ISNUMBER(K15)),"",IF(L15>=Fenster,AVERAGEIFS(K$4:K15,L$4:L15,">"&(L15-Fenster)),IF(AND(Duenn_nVelocity,L15>=3),AVERAGE(K$4:K15),""))) | N15: =IF(ISNUMBER(M15),"",IF(Duenn_nVelocity,IF(ISNUMBER(O14),O14,""),IF(ISNUMBER(O14),O14,""))) -> 31.582478 | O15: =IF(ISNUMBER(M15),M15,IF(ISNUMBER(N15),N15,"")) -> 31.582478 | P15: =COUNT(J$4:J15) -> 12 | Q15: =IF(NOT(ISNUMBER(J15)),"",IF(P15>=Fenster,AVERAGEIFS(J$4:J15,P$4:P15,">"&(P15-Fenster)),IF(AND(Duenn_Kapazitaet,P15>=3),AVERAGE(J$4:J15),""))) -> 71.36 | R15: =IF(ISNUMBER(Q15),"",IF(Duenn_Kapazitaet,IF(ISNUMBER(S14),S14,""),IF(ISNUMBER(S14),S14,""))) | S15: =IF(ISNUMBER(Q15),Q15,IF(ISNUMBER(R15),R15,"")) -> 71.36 | T15: =IF(ISNUMBER(J15),J15,R15) -> 74.2 | U15: =IF(AND(ISNUMBER(N15),ISNUMBER(T15)),MAX(0,ROUNDDOWN(N15/Referenz*T15,Rundung)),IF(ISNUMBER(D15),ROUNDDOWN(D15,Rundung),"")) -> 58.5 | V15: =IF(ISNUMBER(U15),U15*Roadmap_Anteil,"") -> 43.875 | W15: =IF(ISNUMBER(U15),U15-V15,"") -> 14.625 | X15: =IF(AND(ISNUMBER(E15),ISNUMBER(D15),D15<>0),E15/D15,"") | Y15: =IF(AND(ISNUMBER(E15),ISNUMBER(J15),J15>0),E15/J15,"") | AE15: =IF(COUNTIFS('Product values'!$A$2:$A$69,A15,'Product values'!$G$2:$G$69,"<>")=0,"",SUMIFS('Product values'!$G$2:$G$69,'Product values'!$A$2:$A$69,A15)) | AF15: =IF(AND(ISNUMBER(U15),ISNUMBER(AE15)),U15-AE15,"")
A16: 2026.13 | B16: 46197 | C16: 46211 | H16: 75 | I16: Calendar, absences unknown | J16: =IF(ISNUMBER(G16),G16,IF(ISNUMBER(H16),H16,"")) -> 75 | K16: =IF(AND(ISNUMBER(E16),ISNUMBER(J16),J16>0),E16/J16*Referenz,"") | L16: =COUNT(K$4:K16) -> 6 | M16: =IF(NOT(ISNUMBER(K16)),"",IF(L16>=Fenster,AVERAGEIFS(K$4:K16,L$4:L16,">"&(L16-Fenster)),IF(AND(Duenn_nVelocity,L16>=3),AVERAGE(K$4:K16),""))) | N16: =IF(ISNUMBER(M16),"",IF(Duenn_nVelocity,IF(ISNUMBER(O15),O15,""),IF(ISNUMBER(O15),O15,""))) -> 31.582478 | O16: =IF(ISNUMBER(M16),M16,IF(ISNUMBER(N16),N16,"")) -> 31.582478 | P16: =COUNT(J$4:J16) -> 13 | Q16: =IF(NOT(ISNUMBER(J16)),"",IF(P16>=Fenster,AVERAGEIFS(J$4:J16,P$4:P16,">"&(P16-Fenster)),IF(AND(Duenn_Kapazitaet,P16>=3),AVERAGE(J$4:J16),""))) -> 71.16 | R16: =IF(ISNUMBER(Q16),"",IF(Duenn_Kapazitaet,IF(ISNUMBER(S15),S15,""),IF(ISNUMBER(S15),S15,""))) | S16: =IF(ISNUMBER(Q16),Q16,IF(ISNUMBER(R16),R16,"")) -> 71.16 | T16: =IF(ISNUMBER(J16),J16,R16) -> 75 | U16: =IF(AND(ISNUMBER(N16),ISNUMBER(T16)),MAX(0,ROUNDDOWN(N16/Referenz*T16,Rundung)),IF(ISNUMBER(D16),ROUNDDOWN(D16,Rundung),"")) -> 59.2 | V16: =IF(ISNUMBER(U16),U16*Roadmap_Anteil,"") -> 44.4 | W16: =IF(ISNUMBER(U16),U16-V16,"") -> 14.8 | X16: =IF(AND(ISNUMBER(E16),ISNUMBER(D16),D16<>0),E16/D16,"") | Y16: =IF(AND(ISNUMBER(E16),ISNUMBER(J16),J16>0),E16/J16,"") | AE16: =IF(COUNTIFS('Product values'!$A$2:$A$69,A16,'Product values'!$G$2:$G$69,"<>")=0,"",SUMIFS('Product values'!$G$2:$G$69,'Product values'!$A$2:$A$69,A16)) | AF16: =IF(AND(ISNUMBER(U16),ISNUMBER(AE16)),U16-AE16,"")
A17: 2026.14 | B17: 46211 | C17: 46225 | H17: 76 | I17: Calendar, absences unknown | J17: =IF(ISNUMBER(G17),G17,IF(ISNUMBER(H17),H17,"")) -> 76 | K17: =IF(AND(ISNUMBER(E17),ISNUMBER(J17),J17>0),E17/J17*Referenz,"") | L17: =COUNT(K$4:K17) -> 6 | M17: =IF(NOT(ISNUMBER(K17)),"",IF(L17>=Fenster,AVERAGEIFS(K$4:K17,L$4:L17,">"&(L17-Fenster)),IF(AND(Duenn_nVelocity,L17>=3),AVERAGE(K$4:K17),""))) | N17: =IF(ISNUMBER(M17),"",IF(Duenn_nVelocity,IF(ISNUMBER(O16),O16,""),IF(ISNUMBER(O16),O16,""))) -> 31.582478 | O17: =IF(ISNUMBER(M17),M17,IF(ISNUMBER(N17),N17,"")) -> 31.582478 | P17: =COUNT(J$4:J17) -> 14 | Q17: =IF(NOT(ISNUMBER(J17)),"",IF(P17>=Fenster,AVERAGEIFS(J$4:J17,P$4:P17,">"&(P17-Fenster)),IF(AND(Duenn_Kapazitaet,P17>=3),AVERAGE(J$4:J17),""))) -> 72.24 | R17: =IF(ISNUMBER(Q17),"",IF(Duenn_Kapazitaet,IF(ISNUMBER(S16),S16,""),IF(ISNUMBER(S16),S16,""))) | S17: =IF(ISNUMBER(Q17),Q17,IF(ISNUMBER(R17),R17,"")) -> 72.24 | T17: =IF(ISNUMBER(J17),J17,R17) -> 76 | U17: =IF(AND(ISNUMBER(N17),ISNUMBER(T17)),MAX(0,ROUNDDOWN(N17/Referenz*T17,Rundung)),IF(ISNUMBER(D17),ROUNDDOWN(D17,Rundung),"")) -> 60 | V17: =IF(ISNUMBER(U17),U17*Roadmap_Anteil,"") -> 45 | W17: =IF(ISNUMBER(U17),U17-V17,"") -> 15 | X17: =IF(AND(ISNUMBER(E17),ISNUMBER(D17),D17<>0),E17/D17,"") | Y17: =IF(AND(ISNUMBER(E17),ISNUMBER(J17),J17>0),E17/J17,"") | AE17: =IF(COUNTIFS('Product values'!$A$2:$A$69,A17,'Product values'!$G$2:$G$69,"<>")=0,"",SUMIFS('Product values'!$G$2:$G$69,'Product values'!$A$2:$A$69,A17)) | AF17: =IF(AND(ISNUMBER(U17),ISNUMBER(AE17)),U17-AE17,"")
A18: 2026.15 | B18: 46225 | C18: 46239 | H18: 76 | I18: Calendar, absences unknown | J18: =IF(ISNUMBER(G18),G18,IF(ISNUMBER(H18),H18,"")) -> 76 | K18: =IF(AND(ISNUMBER(E18),ISNUMBER(J18),J18>0),E18/J18*Referenz,"") | L18: =COUNT(K$4:K18) -> 6 | M18: =IF(NOT(ISNUMBER(K18)),"",IF(L18>=Fenster,AVERAGEIFS(K$4:K18,L$4:L18,">"&(L18-Fenster)),IF(AND(Duenn_nVelocity,L18>=3),AVERAGE(K$4:K18),""))) | N18: =IF(ISNUMBER(M18),"",IF(Duenn_nVelocity,IF(ISNUMBER(O17),O17,""),IF(ISNUMBER(O17),O17,""))) -> 31.582478 | O18: =IF(ISNUMBER(M18),M18,IF(ISNUMBER(N18),N18,"")) -> 31.582478 | P18: =COUNT(J$4:J18) -> 15 | Q18: =IF(NOT(ISNUMBER(J18)),"",IF(P18>=Fenster,AVERAGEIFS(J$4:J18,P$4:P18,">"&(P18-Fenster)),IF(AND(Duenn_Kapazitaet,P18>=3),AVERAGE(J$4:J18),""))) -> 74.64 | R18: =IF(ISNUMBER(Q18),"",IF(Duenn_Kapazitaet,IF(ISNUMBER(S17),S17,""),IF(ISNUMBER(S17),S17,""))) | S18: =IF(ISNUMBER(Q18),Q18,IF(ISNUMBER(R18),R18,"")) -> 74.64 | T18: =IF(ISNUMBER(J18),J18,R18) -> 76 | U18: =IF(AND(ISNUMBER(N18),ISNUMBER(T18)),MAX(0,ROUNDDOWN(N18/Referenz*T18,Rundung)),IF(ISNUMBER(D18),ROUNDDOWN(D18,Rundung),"")) -> 60 | V18: =IF(ISNUMBER(U18),U18*Roadmap_Anteil,"") -> 45 | W18: =IF(ISNUMBER(U18),U18-V18,"") -> 15 | X18: =IF(AND(ISNUMBER(E18),ISNUMBER(D18),D18<>0),E18/D18,"") | Y18: =IF(AND(ISNUMBER(E18),ISNUMBER(J18),J18>0),E18/J18,"") | AE18: =IF(COUNTIFS('Product values'!$A$2:$A$69,A18,'Product values'!$G$2:$G$69,"<>")=0,"",SUMIFS('Product values'!$G$2:$G$69,'Product values'!$A$2:$A$69,A18)) | AF18: =IF(AND(ISNUMBER(U18),ISNUMBER(AE18)),U18-AE18,"")
A19: 2026.16 | B19: 46239 | C19: 46253 | H19: 76 | I19: Calendar, absences unknown | J19: =IF(ISNUMBER(G19),G19,IF(ISNUMBER(H19),H19,"")) -> 76 | K19: =IF(AND(ISNUMBER(E19),ISNUMBER(J19),J19>0),E19/J19*Referenz,"") | L19: =COUNT(K$4:K19) -> 6 | M19: =IF(NOT(ISNUMBER(K19)),"",IF(L19>=Fenster,AVERAGEIFS(K$4:K19,L$4:L19,">"&(L19-Fenster)),IF(AND(Duenn_nVelocity,L19>=3),AVERAGE(K$4:K19),""))) | N19: =IF(ISNUMBER(M19),"",IF(Duenn_nVelocity,IF(ISNUMBER(O18),O18,""),IF(ISNUMBER(O18),O18,""))) -> 31.582478 | O19: =IF(ISNUMBER(M19),M19,IF(ISNUMBER(N19),N19,"")) -> 31.582478 | P19: =COUNT(J$4:J19) -> 16 | Q19: =IF(NOT(ISNUMBER(J19)),"",IF(P19>=Fenster,AVERAGEIFS(J$4:J19,P$4:P19,">"&(P19-Fenster)),IF(AND(Duenn_Kapazitaet,P19>=3),AVERAGE(J$4:J19),""))) -> 75.44 | R19: =IF(ISNUMBER(Q19),"",IF(Duenn_Kapazitaet,IF(ISNUMBER(S18),S18,""),IF(ISNUMBER(S18),S18,""))) | S19: =IF(ISNUMBER(Q19),Q19,IF(ISNUMBER(R19),R19,"")) -> 75.44 | T19: =IF(ISNUMBER(J19),J19,R19) -> 76 | U19: =IF(AND(ISNUMBER(N19),ISNUMBER(T19)),MAX(0,ROUNDDOWN(N19/Referenz*T19,Rundung)),IF(ISNUMBER(D19),ROUNDDOWN(D19,Rundung),"")) -> 60 | V19: =IF(ISNUMBER(U19),U19*Roadmap_Anteil,"") -> 45 | W19: =IF(ISNUMBER(U19),U19-V19,"") -> 15 | X19: =IF(AND(ISNUMBER(E19),ISNUMBER(D19),D19<>0),E19/D19,"") | Y19: =IF(AND(ISNUMBER(E19),ISNUMBER(J19),J19>0),E19/J19,"") | AE19: =IF(COUNTIFS('Product values'!$A$2:$A$69,A19,'Product values'!$G$2:$G$69,"<>")=0,"",SUMIFS('Product values'!$G$2:$G$69,'Product values'!$A$2:$A$69,A19)) | AF19: =IF(AND(ISNUMBER(U19),ISNUMBER(AE19)),U19-AE19,"")

Sheet Sprint data
A1: Sprint | B1: State of the absences (unknown, expected, confirmed) | C1: Forecast PLAN at planning, frozen (PT) | D1: Carry-over (PT) | E1: Backlog (PT) | F1: Corrections of remaining effort (separated by spaces) | G1: Of which not finished (PT) | H1: Additionally done (PT) | I1: Of which with production access, planning (PT) | J1: Of which with production access, done (PT) | K1: Note
A2: 2026.1 | B2: unknown | C2: 25.5
A3: 2026.2 | B3: unknown | C3: 27
A4: 2026.3 | B4: unknown
A5: 2026.4 | B5: unknown | C5: 30
A6: 2026.5 | B6: unknown | I6: 3 | J6: 2.5
A7: 2026.6 | B7: unknown
A8: 2026.7
A9: 2026.8
A10: 2026.9

Sheet Absences
A1: Sprint | B1: Person (ID) | C1: Name | D1: days | E1: Kind (absences = confirmed, expected_absences = announced)

Sheet People
A1: ID | B1: Name | C1: Country | D1: Region | E1: Work week | F1: Production access | G1: Member from | H1: Member until | I1: FTE
A2: anna | B2: Anna | G2: 45658 | I2: 1
A3: ben | B3: Ben | G3: 45658 | H3: 46265 | I3: 1
A4: ben | B4: Ben | G4: 46266 | I4: 0.5
A5: cem | B5: Cem | D5: BY | G5: 45658 | I5: 1
A6: dana | B6: Dana | C6: US | D6: CA | G6: 45809 | I6: 1
A7: eli | B7: Eli | C7: CN | G7: 45809 | I7: 0.8
A8: fadi | B8: Fadi | C8: SA | G8: 46023 | I8: 1
A9: gina | B9: Gina | E9: mon,tue,wed,thu | G9: 45658 | I9: 1
A10: hugo | B10: Hugo | E10: sun-thu | G10: 45658 | I10: 1
A11: ines | B11: Ines | F11: TRUE | G11: 45658 | H11: 46101 | I11: 1
A12: jonas | B12: Jonas | F12: TRUE | G12: 46280 | I12: 1

Sheet Product list
A1: ID | B1: Name | C1: PO | D1: Handled from | E1: Handled until | F1: Fixed share (0–1)
A2: web | B2: Web | C2: Alex | F2: 0.4
A3: app | B3: App | C3: Alex | F3: 0.35
A4: api | B4: API | C4: Bea
A5: old | B5: Old | C5: Bea | E5: 46082
A6: new | B6: New | D6: 46085

Sheet Product values
A1: Sprint | B1: Product (ID) | C1: Product | D1: PO | E1: Standard (PT) | F1: PO pre-planning (PT) | G1: Planning (PT) | H1: Done (PT) | I1: of which production access (planning) (PT) | J1: of which production access (done) (PT) | K1: Planning without production access (PT) | L1: Done without production access (PT)
A2: 2026.1 | B2: web | C2: Web | D2: Alex | E2: 7.65 | F2: 10 | G2: 11 | H2: 10.5 | I2: 2 | J2: 1.5 | K2: =IF(AND(ISNUMBER(G2),ISNUMBER(I2)),G2-I2,"") -> 9 | L2: =IF(AND(ISNUMBER(H2),ISNUMBER(J2)),H2-J2,"") -> 9
A3: 2026.1 | B3: app | C3: App | D3: Alex | E3: 6.69375 | F3: 9 | G3: 9 | H3: 9 | K3: =IF(AND(ISNUMBER(G3),ISNUMBER(I3)),G3-I3,"") | L3: =IF(AND(ISNUMBER(H3),ISNUMBER(J3)),H3-J3,"")
A4: 2026.1 | B4: api | C4: API | D4: Bea | E4: 2.390625 | F4: 6 | G4: 5.5 | H4: 5 | K4: =IF(AND(ISNUMBER(G4),ISNUMBER(I4)),G4-I4,"") | L4: =IF(AND(ISNUMBER(H4),ISNUMBER(J4)),H4-J4,"")
A5: 2026.1 | B5: old | C5: Old | D5: Bea | E5: 2.390625 | H5: 1 | K5: =IF(AND(ISNUMBER(G5),ISNUMBER(I5)),G5-I5,"") | L5: =IF(AND(ISNUMBER(H5),ISNUMBER(J5)),H5-J5,"")
A6: 2026.1 | B6: aa | C6: aa | G6: 1 | K6: =IF(AND(ISNUMBER(G6),ISNUMBER(I6)),G6-I6,"") | L6: =IF(AND(ISNUMBER(H6),ISNUMBER(J6)),H6-J6,"")
A7: 2026.1 | B7: zz | C7: zz | H7: 0.5 | K7: =IF(AND(ISNUMBER(G7),ISNUMBER(I7)),G7-I7,"") | L7: =IF(AND(ISNUMBER(H7),ISNUMBER(J7)),H7-J7,"")
A8: 2026.2 | B8: web | C8: Web | D8: Alex | E8: 8.1 | G8: 12 | H8: 12.5 | K8: =IF(AND(ISNUMBER(G8),ISNUMBER(I8)),G8-I8,"") | L8: =IF(AND(ISNUMBER(H8),ISNUMBER(J8)),H8-J8,"")
A9: 2026.2 | B9: app | C9: App | D9: Alex | E9: 7.0875 | G9: 9 | K9: =IF(AND(ISNUMBER(G9),ISNUMBER(I9)),G9-I9,"") | L9: =IF(AND(ISNUMBER(H9),ISNUMBER(J9)),H9-J9,"")
A10: 2026.2 | B10: api | C10: API | D10: Bea | E10: 2.53125 | G10: 6 | H10: 6.5 | I10: 1 | K10: =IF(AND(ISNUMBER(G10),ISNUMBER(I10)),G10-I10,"") -> 5 | L10: =IF(AND(ISNUMBER(H10),ISNUMBER(J10)),H10-J10,"")
A11: 2026.2 | B11: old | C11: Old | D11: Bea | E11: 2.53125 | H11: 0 | K11: =IF(AND(ISNUMBER(G11),ISNUMBER(I11)),G11-I11,"") | L11: =IF(AND(ISNUMBER(H11),ISNUMBER(J11)),H11-J11,"")
A12: 2026.3 | B12: web | C12: Web | D12: Alex | E12: 9.9 | G12: 11 | H12: 10 | I12: 30 | K12: =IF(AND(ISNUMBER(G12),ISNUMBER(I12)),G12-I12,"") -> -19 | L12: =IF(AND(ISNUMBER(H12),ISNUMBER(J12)),H12-J12,"")
A13: 2026.3 | B13: app | C13: App | D13: Alex | E13: 8.6625 | K13: =IF(AND(ISNUMBER(G13),ISNUMBER(I13)),G13-I13,"") | L13: =IF(AND(ISNUMBER(H13),ISNUMBER(J13)),H13-J13,"")
A14: 2026.3 | B14: api | C14: API | D14: Bea | E14: 3.09375 | G14: 7 | H14: 7 | K14: =IF(AND(ISNUMBER(G14),ISNUMBER(I14)),G14-I14,"") | L14: =IF(AND(ISNUMBER(H14),ISNUMBER(J14)),H14-J14,"")
A15: 2026.3 | B15: old | C15: Old | D15: Bea | E15: 3.09375 | K15: =IF(AND(ISNUMBER(G15),ISNUMBER(I15)),G15-I15,"") | L15: =IF(AND(ISNUMBER(H15),ISNUMBER(J15)),H15-J15,"")
A16: 2026.3 | B16: new | C16: New | H16: 2 | J16: 1 | K16: =IF(AND(ISNUMBER(G16),ISNUMBER(I16)),G16-I16,"") | L16: =IF(AND(ISNUMBER(H16),ISNUMBER(J16)),H16-J16,"") -> 1
A17: 2026.4 | B17: web | C17: Web | D17: Alex | E17: 9 | K17: =IF(AND(ISNUMBER(G17),ISNUMBER(I17)),G17-I17,"") | L17: =IF(AND(ISNUMBER(H17),ISNUMBER(J17)),H17-J17,"")
A18: 2026.4 | B18: app | C18: App | D18: Alex | E18: 7.875 | H18: 8 | K18: =IF(AND(ISNUMBER(G18),ISNUMBER(I18)),G18-I18,"") | L18: =IF(AND(ISNUMBER(H18),ISNUMBER(J18)),H18-J18,"")
A19: 2026.4 | B19: api | C19: API | D19: Bea | E19: 2.8125 | K19: =IF(AND(ISNUMBER(G19),ISNUMBER(I19)),G19-I19,"") | L19: =IF(AND(ISNUMBER(H19),ISNUMBER(J19)),H19-J19,"")
A20: 2026.4 | B20: old | C20: Old | D20: Bea | E20: 2.8125 | K20: =IF(AND(ISNUMBER(G20),ISNUMBER(I20)),G20-I20,"") | L20: =IF(AND(ISNUMBER(H20),ISNUMBER(J20)),H20-J20,"")
A21: 2026.4 | B21: new | C21: New | H21: 3 | K21: =IF(AND(ISNUMBER(G21),ISNUMBER(I21)),G21-I21,"") | L21: =IF(AND(ISNUMBER(H21),ISNUMBER(J21)),H21-J21,"")
A22: 2026.5 | B22: web | C22: Web | D22: Alex | E22: 10.2 | K22: =IF(AND(ISNUMBER(G22),ISNUMBER(I22)),G22-I22,"") | L22: =IF(AND(ISNUMBER(H22),ISNUMBER(J22)),H22-J22,"")
A23: 2026.5 | B23: app | C23: App | D23: Alex | E23: 8.925 | K23: =IF(AND(ISNUMBER(G23),ISNUMBER(I23)),G23-I23,"") | L23: =IF(AND(ISNUMBER(H23),ISNUMBER(J23)),H23-J23,"")
A24: 2026.5 | B24: api | C24: API | D24: Bea | E24: 3.1875 | K24: =IF(AND(ISNUMBER(G24),ISNUMBER(I24)),G24-I24,"") | L24: =IF(AND(ISNUMBER(H24),ISNUMBER(J24)),H24-J24,"")
A25: 2026.5 | B25: new | C25: New | E25: 3.1875 | K25: =IF(AND(ISNUMBER(G25),ISNUMBER(I25)),G25-I25,"") | L25: =IF(AND(ISNUMBER(H25),ISNUMBER(J25)),H25-J25,"")
A26: 2026.6 | B26: web | C26: Web | D26: Alex | E26: 9.6 | F26: 9 | K26: =IF(AND(ISNUMBER(G26),ISNUMBER(I26)),G26-I26,"") | L26: =IF(AND(ISNUMBER(H26),ISNUMBER(J26)),H26-J26,"")
A27: 2026.6 | B27: app | C27: App | D27: Alex | E27: 8.4 | F27: 8 | K27: =IF(AND(ISNUMBER(G27),ISNUMBER(I27)),G27-I27,"") | L27: =IF(AND(ISNUMBER(H27),ISNUMBER(J27)),H27-J27,"")
A28: 2026.6 | B28: api | C28: API | D28: Bea | E28: 3 | K28: =IF(AND(ISNUMBER(G28),ISNUMBER(I28)),G28-I28,"") | L28: =IF(AND(ISNUMBER(H28),ISNUMBER(J28)),H28-J28,"")
A29: 2026.6 | B29: new | C29: New | E29: 3 | K29: =IF(AND(ISNUMBER(G29),ISNUMBER(I29)),G29-I29,"") | L29: =IF(AND(ISNUMBER(H29),ISNUMBER(J29)),H29-J29,"")
A30: 2026.7 | B30: web | C30: Web | D30: Alex | E30: 15.9 | K30: =IF(AND(ISNUMBER(G30),ISNUMBER(I30)),G30-I30,"") | L30: =IF(AND(ISNUMBER(H30),ISNUMBER(J30)),H30-J30,"")
A31: 2026.7 | B31: app | C31: App | D31: Alex | E31: 13.9125 | K31: =IF(AND(ISNUMBER(G31),ISNUMBER(I31)),G31-I31,"") | L31: =IF(AND(ISNUMBER(H31),ISNUMBER(J31)),H31-J31,"")
A32: 2026.7 | B32: api | C32: API | D32: Bea | E32: 4.96875 | K32: =IF(AND(ISNUMBER(G32),ISNUMBER(I32)),G32-I32,"") | L32: =IF(AND(ISNUMBER(H32),ISNUMBER(J32)),H32-J32,"")
A33: 2026.7 | B33: new | C33: New | E33: 4.96875 | K33: =IF(AND(ISNUMBER(G33),ISNUMBER(I33)),G33-I33,"") | L33: =IF(AND(ISNUMBER(H33),ISNUMBER(J33)),H33-J33,"")
A34: 2026.8 | B34: web | C34: Web | D34: Alex | E34: 18 | K34: =IF(AND(ISNUMBER(G34),ISNUMBER(I34)),G34-I34,"") | L34: =IF(AND(ISNUMBER(H34),ISNUMBER(J34)),H34-J34,"")
A35: 2026.8 | B35: app | C35: App | D35: Alex | E35: 15.75 | K35: =IF(AND(ISNUMBER(G35),ISNUMBER(I35)),G35-I35,"") | L35: =IF(AND(ISNUMBER(H35),ISNUMBER(J35)),H35-J35,"")
A36: 2026.8 | B36: api | C36: API | D36: Bea | E36: 5.625 | K36: =IF(AND(ISNUMBER(G36),ISNUMBER(I36)),G36-I36,"") | L36: =IF(AND(ISNUMBER(H36),ISNUMBER(J36)),H36-J36,"")
A37: 2026.8 | B37: new | C37: New | E37: 5.625 | K37: =IF(AND(ISNUMBER(G37),ISNUMBER(I37)),G37-I37,"") | L37: =IF(AND(ISNUMBER(H37),ISNUMBER(J37)),H37-J37,"")
A38: 2026.9 | B38: web | C38: Web | D38: Alex | E38: 16.71 | K38: =IF(AND(ISNUMBER(G38),ISNUMBER(I38)),G38-I38,"") | L38: =IF(AND(ISNUMBER(H38),ISNUMBER(J38)),H38-J38,"")
A39: 2026.9 | B39: app | C39: App | D39: Alex | E39: 14.62125 | K39: =IF(AND(ISNUMBER(G39),ISNUMBER(I39)),G39-I39,"") | L39: =IF(AND(ISNUMBER(H39),ISNUMBER(J39)),H39-J39,"")
A40: 2026.9 | B40: api | C40: API | D40: Bea | E40: 5.221875 | K40: =IF(AND(ISNUMBER(G40),ISNUMBER(I40)),G40-I40,"") | L40: =IF(AND(ISNUMBER(H40),ISNUMBER(J40)),H40-J40,"")
...

Sheet Prognoses
A1: Sprint | B1: Time | C1: Comment | D1: Commitment (PT) | E1: Expected not finished (PT) | F1: Additionally done (PT) | G1: Expected done | H1: Target sprint | I1: Forecast PLAN | J1: Pre-planning per product (ID=value; …)

Sheet Trend
A1: Sprint | B1: norm. velocity | C1: Ø norm. velocity | D1: norm. velocity trend | E1: Forecast PLAN | F1: Velocity | G1: Commitment
A2: ='Forecast'!A4 -> 2026.1 | B2: =IF(ISNUMBER('Forecast'!K4),'Forecast'!K4,NA()) -> 30 | C2: =IF(ISNUMBER('Forecast'!M4),'Forecast'!M4,NA()) -> #N/A | D2: =IF(ISNUMBER('Forecast'!N4),'Forecast'!N4,NA()) -> #N/A | E2: =IF(ISNUMBER('Forecast'!U4),'Forecast'!U4,NA()) -> 32 | F2: =IF(ISNUMBER('Forecast'!E4),'Forecast'!E4,NA()) -> 30 | G2: =IF(ISNUMBER('Forecast'!D4),'Forecast'!D4,NA()) -> 32
A3: ='Forecast'!A5 -> 2026.2 | B3: =IF(ISNUMBER('Forecast'!K5),'Forecast'!K5,NA()) -> 30.909091 | C3: =IF(ISNUMBER('Forecast'!M5),'Forecast'!M5,NA()) -> #N/A | D3: =IF(ISNUMBER('Forecast'!N5),'Forecast'!N5,NA()) -> #N/A | E3: =IF(ISNUMBER('Forecast'!U5),'Forecast'!U5,NA()) -> 35 | F3: =IF(ISNUMBER('Forecast'!E5),'Forecast'!E5,NA()) -> 34 | G3: =IF(ISNUMBER('Forecast'!D5),'Forecast'!D5,NA()) -> 35
A4: ='Forecast'!A6 -> 2026.3 | B4: =IF(ISNUMBER('Forecast'!K6),'Forecast'!K6,NA()) -> 29.473684 | C4: =IF(ISNUMBER('Forecast'!M6),'Forecast'!M6,NA()) -> #N/A | D4: =IF(ISNUMBER('Forecast'!N6),'Forecast'!N6,NA()) -> #N/A | E4: =IF(ISNUMBER('Forecast'!U6),'Forecast'!U6,NA()) -> 33 | F4: =IF(ISNUMBER('Forecast'!E6),'Forecast'!E6,NA()) -> 28 | G4: =IF(ISNUMBER('Forecast'!D6),'Forecast'!D6,NA()) -> 33
A5: ='Forecast'!A7 -> 2026.4 | B5: =IF(ISNUMBER('Forecast'!K7),'Forecast'!K7,NA()) -> 34.285714 | C5: =IF(ISNUMBER('Forecast'!M7),'Forecast'!M7,NA()) -> #N/A | D5: =IF(ISNUMBER('Forecast'!N7),'Forecast'!N7,NA()) -> #N/A | E5: =IF(ISNUMBER('Forecast'!U7),'Forecast'!U7,NA()) -> 36 | F5: =IF(ISNUMBER('Forecast'!E7),'Forecast'!E7,NA()) -> 36 | G5: =IF(ISNUMBER('Forecast'!D7),'Forecast'!D7,NA()) -> 36
A6: ='Forecast'!A8 -> 2026.5 | B6: =IF(ISNUMBER('Forecast'!K8),'Forecast'!K8,NA()) -> 33 | C6: =IF(ISNUMBER('Forecast'!M8),'Forecast'!M8,NA()) -> 31.533698 | D6: =IF(ISNUMBER('Forecast'!N8),'Forecast'!N8,NA()) -> #N/A | E6: =IF(ISNUMBER('Forecast'!U8),'Forecast'!U8,NA()) -> 34 | F6: =IF(ISNUMBER('Forecast'!E8),'Forecast'!E8,NA()) -> 33 | G6: =IF(ISNUMBER('Forecast'!D8),'Forecast'!D8,NA()) -> 34
A7: ='Forecast'!A9 -> 2026.6 | B7: =IF(ISNUMBER('Forecast'!K9),'Forecast'!K9,NA()) -> 30.243902 | C7: =IF(ISNUMBER('Forecast'!M9),'Forecast'!M9,NA()) -> 31.582478 | D7: =IF(ISNUMBER('Forecast'!N9),'Forecast'!N9,NA()) -> #N/A | E7: =IF(ISNUMBER('Forecast'!U9),'Forecast'!U9,NA()) -> 32 | F7: =IF(ISNUMBER('Forecast'!E9),'Forecast'!E9,NA()) -> 31 | G7: =IF(ISNUMBER('Forecast'!D9),'Forecast'!D9,NA()) -> 32
A8: ='Forecast'!A10 -> 2026.7 | B8: =IF(ISNUMBER('Forecast'!K10),'Forecast'!K10,NA()) -> #N/A | C8: =IF(ISNUMBER('Forecast'!M10),'Forecast'!M10,NA()) -> #N/A | D8: =IF(ISNUMBER('Forecast'!N10),'Forecast'!N10,NA()) -> 31.582478 | E8: =IF(ISNUMBER('Forecast'!U10),'Forecast'!U10,NA()) -> 53 | F8: =IF(ISNUMBER('Forecast'!E10),'Forecast'!E10,NA()) -> #N/A | G8: =IF(ISNUMBER('Forecast'!D10),'Forecast'!D10,NA()) -> #N/A
A9: ='Forecast'!A11 -> 2026.8 | B9: =IF(ISNUMBER('Forecast'!K11),'Forecast'!K11,NA()) -> #N/A | C9: =IF(ISNUMBER('Forecast'!M11),'Forecast'!M11,NA()) -> #N/A | D9: =IF(ISNUMBER('Forecast'!N11),'Forecast'!N11,NA()) -> 31.582478 | E9: =IF(ISNUMBER('Forecast'!U11),'Forecast'!U11,NA()) -> 60 | F9: =IF(ISNUMBER('Forecast'!E11),'Forecast'!E11,NA()) -> #N/A | G9: =IF(ISNUMBER('Forecast'!D11),'Forecast'!D11,NA()) -> #N/A
A10: ='Forecast'!A12 -> 2026.9 | B10: =IF(ISNUMBER('Forecast'!K12),'Forecast'!K12,NA()) -> #N/A | C10: =IF(ISNUMBER('Forecast'!M12),'Forecast'!M12,NA()) -> #N/A | D10: =IF(ISNUMBER('Forecast'!N12),'Forecast'!N12,NA()) -> 31.582478 | E10: =IF(ISNUMBER('Forecast'!U12),'Forecast'!U12,NA()) -> 55.7 | F10: =IF(ISNUMBER('Forecast'!E12),'Forecast'!E12,NA()) -> #N/A | G10: =IF(ISNUMBER('Forecast'!D12),'Forecast'!D12,NA()) -> #N/A
A11: ='Forecast'!A13 -> 2026.10 | B11: =IF(ISNUMBER('Forecast'!K13),'Forecast'!K13,NA()) -> #N/A | C11: =IF(ISNUMBER('Forecast'!M13),'Forecast'!M13,NA()) -> #N/A | D11: =IF(ISNUMBER('Forecast'!N13),'Forecast'!N13,NA()) -> 31.582478 | E11: =IF(ISNUMBER('Forecast'!U13),'Forecast'!U13,NA()) -> 50.5 | F11: =IF(ISNUMBER('Forecast'!E13),'Forecast'!E13,NA()) -> #N/A | G11: =IF(ISNUMBER('Forecast'!D13),'Forecast'!D13,NA()) -> #N/A
A12: ='Forecast'!A14 -> 2026.11 | B12: =IF(ISNUMBER('Forecast'!K14),'Forecast'!K14,NA()) -> #N/A | C12: =IF(ISNUMBER('Forecast'!M14),'Forecast'!M14,NA()) -> #N/A | D12: =IF(ISNUMBER('Forecast'!N14),'Forecast'!N14,NA()) -> 31.582478 | E12: =IF(ISNUMBER('Forecast'!U14),'Forecast'!U14,NA()) -> 56.8 | F12: =IF(ISNUMBER('Forecast'!E14),'Forecast'!E14,NA()) -> #N/A | G12: =IF(ISNUMBER('Forecast'!D14),'Forecast'!D14,NA()) -> #N/A
A13: ='Forecast'!A15 -> 2026.12 | B13: =IF(ISNUMBER('Forecast'!K15),'Forecast'!K15,NA()) -> #N/A | C13: =IF(ISNUMBER('Forecast'!M15),'Forecast'!M15,NA()) -> #N/A | D13: =IF(ISNUMBER('Forecast'!N15),'Forecast'!N15,NA()) -> 31.582478 | E13: =IF(ISNUMBER('Forecast'!U15),'Forecast'!U15,NA()) -> 58.5 | F13: =IF(ISNUMBER('Forecast'!E15),'Forecast'!E15,NA()) -> #N/A | G13: =IF(ISNUMBER('Forecast'!D15),'Forecast'!D15,NA()) -> #N/A
... A17: ='Forecast'!A19 -> 2026.16 | B17: =IF(ISNUMBER('Forecast'!K19),'Forecast'!K19,NA()) -> #N/A | C17: =IF(ISNUMBER('Forecast'!M19),'Forecast'!M19,NA()) -> #N/A | D17: =IF(ISNUMBER('Forecast'!N19),'Forecast'!N19,NA()) -> 31.582478 | E17: =IF(ISNUMBER('Forecast'!U19),'Forecast'!U19,NA()) -> 60 | F17: =IF(ISNUMBER('Forecast'!E19),'Forecast'!E19,NA()) -> #N/A | G17: =IF(ISNUMBER('Forecast'!D19),'Forecast'!D19,NA()) -> #N/A
